{"uuid": "2411cd46-5205-4833-a668-f7fc999c5da6", "children": ["7f54ba52-e9f3-4960-83e9-7056823e38d1"], "befores": [{"name": "appium_driver", "status": "broken", "statusDetails": {"message": "selenium.common.exceptions.WebDriverException: Message: An unknown server-side error occurred while processing the command. Original error: The instrumentation process cannot be initialized within 30000ms timeout. Make sure the application under test does not crash and investigate the logcat output. You could also try to increase the value of 'uiautomator2ServerLaunchTimeout' capability\nStacktrace:\nUnknownError: An unknown server-side error occurred while processing the command. Original error: The instrumentation process cannot be initialized within 30000ms timeout. Make sure the application under test does not crash and investigate the logcat output. You could also try to increase the value of 'uiautomator2ServerLaunchTimeout' capability\n    at getResponseForW3CError (/tmp/.mount_AppiumWV61RE/resources/app/node_modules/appium/node_modules/appium-base-driver/lib/protocol/errors.js:804:9)\n    at asyncHandler (/tmp/.mount_AppiumWV61RE/resources/app/node_modules/appium/node_modules/appium-base-driver/lib/protocol/protocol.js:380:37)\n", "trace": "  File \"/home/ezetap-10182/PycharmProjects/GoIbibo/venv/lib/python3.8/site-packages/pluggy/_callers.py\", line 39, in _multicall\n    res = hook_impl.function(*args)\n  File \"/home/ezetap-10182/PycharmProjects/GoIbibo/venv/lib/python3.8/site-packages/_pytest/fixtures.py\", line 1126, in pytest_fixture_setup\n    result = call_fixture_func(fixturefunc, request, kwargs)\n  File \"/home/ezetap-10182/PycharmProjects/GoIbibo/venv/lib/python3.8/site-packages/_pytest/fixtures.py\", line 925, in call_fixture_func\n    fixture_result = next(generator)\n  File \"/home/ezetap-10182/PycharmProjects/GoIbibo/TestCases/conftest.py\", line 23, in appium_driver\n    driver = webdriver.Remote('http://localhost:4723/wd/hub', desired_caps)\n  File \"/home/ezetap-10182/PycharmProjects/GoIbibo/venv/lib/python3.8/site-packages/appium/webdriver/webdriver.py\", line 273, in __init__\n    super().__init__(\n  File \"/home/ezetap-10182/PycharmProjects/GoIbibo/venv/lib/python3.8/site-packages/selenium/webdriver/remote/webdriver.py\", line 268, in __init__\n    self.start_session(capabilities, browser_profile)\n  File \"/home/ezetap-10182/PycharmProjects/GoIbibo/venv/lib/python3.8/site-packages/appium/webdriver/webdriver.py\", line 364, in start_session\n    response = self.execute(RemoteCommand.NEW_SESSION, parameters)\n  File \"/home/ezetap-10182/PycharmProjects/GoIbibo/venv/lib/python3.8/site-packages/selenium/webdriver/remote/webdriver.py\", line 424, in execute\n    self.error_handler.check_response(response)\n  File \"/home/ezetap-10182/PycharmProjects/GoIbibo/venv/lib/python3.8/site-packages/selenium/webdriver/remote/errorhandler.py\", line 247, in check_response\n    raise exception_class(message, screen, stacktrace)\n"}, "start": 1643896053917, "stop": 1643896085692}], "start": 1643896053917, "stop": 1643896085714}